Workbook

Sheet Sumario
M3: USD to EU | R3: FALSE
M4: =IFERROR(__xludf.DUMMYFUNCTION("ARRAYFORMULA({NOW(), GOOGLEFINANCE(""CURRENCY:USDEUR"")})"),46288.715450601856) -> 46288.715 | N4: =IFERROR(__xludf.DUMMYFUNCTION("""COMPUTED_VALUE"""),0.87762) -> 0.87762 | R4: FALSE
R5: FALSE
C6: Mês | D6: - | E6: Total EURO | F6: Total USD | G6: Total USD to EUR | H6: Total EUR | I6: Dividendos EU | J6: Dividendos US | K6: TOTAL | R6: FALSE
C7: 1 | D7: janeiro | E7: =JAN!L3 -> 0 | F7: =JAN!M3 -> 62.98 | G7: =F7*$N$4 -> 55.272508 | H7: =E7+G7 -> 55.272508 | I7: =0.04+0.26+0.04+2.53+0.01+0.02+0.23+0.48+0.24+2.53 -> 6.38 | J7: =0.06+0.07+0.06+0.06+0.02+0.03 -> 0.3 | K7: =H7+I7+(J7*$N$4) -> 61.915794 | R7: FALSE
C8: 2 | D8: fevereiro | E8: =FEV!L3 -> 0 | F8: =FEV!M3 -> 65.8 | G8: =F8*$N$4 -> 57.747396 | H8: =E8+G8 -> 57.747396 | I8: =1.87+0.05+0.01 -> 1.93 | J8: =0.11+0.1+0.08+0.12+0.17+0.11+0.15+0.29+0.08+0.08+0.02+0.02 -> 1.33 | K8: =H8+I8+(J8*$N$4) -> 60.844631 | R8: FALSE
C9: 3 | D9: março | E9: =MAR!L3 -> 0 | F9: =MAR!M3 -> 297.24 | G9: =F9*$N$4 -> 260.86377 | H9: =E9+G9 -> 260.86377 | I9: =0.01+0.04+0.01+0.03+0.04+3 -> 3.13 | J9: =0.14+0.2+0.08+0.13+0.02 -> 0.57 | K9: =H9+I9+(J9*$N$4) -> 264.49401 | R9: FALSE
C10: 4 | D10: abril | E10: =ABR!L3 -> 11.31 | F10: =ABR!M3 -> 388.56 | G10: =F10*$N$4 -> 341.00803 | H10: =E10+G10 -> 352.31803 | I10: =0.02+0.07+0.06+0.04+0.05+0.05+0.29+0.02+0.01+0.05+0.78+0.09+0.08+0.03+0.7+12.88+0.61+0.27+0.04+0.64+2.55+0.15+0.14+0.39 -> 20.01 | J10: =0.23+0.2+0.17+0.18+0.17+0.05+0.06+0.25+0.1+0.17+0.17+0.27+0.37+0.03+0.09+0.01 -> 2.52 | K10: =H10+I10+(J10*$N$4) -> 374.53963 | R10: FALSE
C11: 5 | D11: maio | E11: =MAI!L3 -> 0 | F11: =MAI!M3 -> 606.31 | G11: =F11*$N$4 -> 532.10978 | H11: =E11+G11 -> 532.10978 | I11: =0.29+0.01+0.14+0.14+0.15+0.15+0.13+0.15+0.16+3.68+2.38+0.66+0.13+0.31+0.18+0.14+0.02+0.28+0.13+0.13 -> 9.36 | J11: =0.06+0.03+0.18+0.18+0.18+0.14 -> 0.77 | K11: =H11+I11+(J11*$N$4) -> 542.14555 | N11: =J12*N4 -> 0.2018526 | R11: FALSE
C12: 6 | D12: junho | E12: =JUN!L3 -> 0 | F12: =JUN!M3 -> 127.55 | G12: =F12*$N$4 -> 111.94043 | H12: =E12+G12 -> 111.94043 | I12: =0.22+0.06+0.17+0.09+0.17+3.51+0.91+0.15+0.08+0.74 -> 6.1 | J12: =0.19+0.04 -> 0.23 | K12: =H12+I12+(J12*$N$4) -> 118.24228 | R12: FALSE
C13: 7 | D13: julho | E13: =JUL!L3 -> 0 | F13: =JUL!M3 -> -429.78 | G13: =F13*$N$4 -> -377.18352 | H13: =E13+G13 -> -377.18352 | I13: =28.41+0.07+0.07+0.16+0.07+0.07+0.28+0.09+0.04+0.07+0.04+0.15+0.02+0.36+0.06+0.02 -> 29.98 | J13: =0.01+3.05+0.18 -> 3.24 | K13: =H13+I13+(J13*$N$4) -> -344.36003 | R13: FALSE
C14: 8 | D14: agosto | E14: =AGO!L3 -> 76.77 | F14: =AGO!M3 -> -1446.55 | G14: =F14*$N$4 -> -1269.5212 | H14: =E14+G14 -> -1192.7512 | I14: =0.15+0.12+0.14+0.01+0.14+0.18+0.16 -> 0.9 | J14: =0.12+0.11+0.12+0.12+0.11+0.16+0.63+0.57+0.55+0.4+0.41+0.49+0.53+0.54+0.64 -> 5.5 | K14: =H14+I14+(J14*$N$4) -> -1187.0243 | R14: FALSE
C15: 9 | D15: setembro | E15: =SET!L3 -> 0 | F15: =SET!M3 -> -675.07 | G15: =F15*$N$4 -> -592.45493 | H15: =E15+G15 -> -592.45493 | I15: =1.18 -> 1.18 | J15: =18.05 -> 18.05 | K15: =H15+I15+(J15*$N$4) -> -575.43389 | R15: FALSE
C16: 10 | D16: outubro | E16: =OUT!L3 -> 0 | F16: =OUT!M3 -> 0 | G16: =F16*$N$4 -> 0 | H16: =E16+G16 -> 0 | K16: =H16+I16+(J16*$N$4) -> 0 | R16: FALSE
C17: 11 | D17: novembro | E17: =NOV!L3 -> 0 | F17: =NOV!M3 -> 0 | G17: =F17*$N$4 -> 0 | H17: =E17+G17 -> 0 | K17: =H17+I17+(J17*$N$4) -> 0 | R17: FALSE
C18: 12 | D18: dezembro | E18: =DEZ!L3 -> 0 | F18: =DEZ!M3 -> 0 | G18: =F18*$N$4 -> 0 | H18: =E18+G18 -> 0 | K18: =H18+I18+(J18*$N$4) -> 0 | N18: NET | O18: TAX | R18: FALSE
D19: total | E19: =sum(E7:E18) -> 88.08 | F19: =sum(F7:F18) -> -1002.96 | G19: =sum(G7:G18) -> -880.21776 | H19: =E19+G19 -> -792.13776 | I19: =SUM(I7:I18) -> 78.97 | J19: =SUM(J7:J18) -> 32.51 | K19: =SUM(K7:K18) -> -684.63633 | N19: =K19-(K19*28%) -> -492.93816 | O19: =K19*28% -> -191.69817 | R19: FALSE
N20: =N19/12 -> -41.07818 | R20: FALSE
N21: =K19/12 -> -57.053027 | R21: FALSE
R22: FALSE
R23: FALSE
R24: FALSE
R25: FALSE
R26: FALSE
R27: FALSE
R28: FALSE
R29: FALSE
R30: FALSE
R31: FALSE
R32: FALSE
R33: FALSE
... R1001: FALSE

Sheet JAN
K2: Valor Conta | L2: EUR | M2: USD | N2: USD em EU
K3: Total | L3: =sum(E7:E37) -> 0 | M3: =sum(F7:F37) -> 62.98 | N3: =M3*Sumario!N4 -> 55.272508 | O3: =Sumario!N4 -> 0.87762
B4: JAN
B5: Posicao | C5: Data | D5: Preço Abertura | E5: Lucro EU | F5: Lucro USD | G5: Total EUR
H6: Goal
C7: Day 1 | G7: =E7+(F7*$O$3) -> 0 | H7: =G7/$O$9 -> 0 | I7: =315+G7 -> 315
C8: Day 2 | F8: =11.61 -> 11.61 | G8: =E8+(F8*$O$3) -> 10.189168 | H8: =G8/$O$9 -> 0.085589013 | I8: =315+G8 -> 325.18917 | N8: Goal | O8: 2500 | P8: =O8-Sumario!K7 -> 2438.0842
C9: Day 3 | G9: =E9+(F9*$O$3) -> 0 | H9: =G9/$O$9 -> 0 | I9: =315+G9 -> 315 | L9: 7245 | N9: Goal Day | O9: =O8/21 -> 119.04762 | P9: =P8/O8 -> 0.97523368
C10: Day 4 | G10: =E10+(F10*$O$3) -> 0 | H10: =G10/$O$9 -> 0 | I10: =315+G10 -> 315 | L10: =L9+Sumario!K16 -> 7245
C11: Day 5 | F11: =6.15+7.5 -> 13.65 | G11: =E11+(F11*$O$3) -> 11.979513 | H11: =G11/$O$9 -> 0.10062791 | I11: =315+G11 -> 326.97951
C12: Day 6 | F12: =1.65+1.13+2.12+6.45+9.2+9.2 -> 29.75 | G12: =E12+(F12*$O$3) -> 26.109195 | H12: =G12/$O$9 -> 0.21931724 | I12: =315+G12 -> 341.10919
C13: Day 7 | G13: =E13+(F13*$O$3) -> 0 | H13: =G13/$O$9 -> 0 | I13: =315+G13 -> 315
C14: Day 8 | G14: =E14+(F14*$O$3) -> 0 | H14: =G14/$O$9 -> 0 | I14: =315+G14 -> 315
C15: Day 9 | F15: =3.3 -> 3.3 | G15: =E15+(F15*$O$3) -> 2.896146 | H15: =G15/$O$9 -> 0.024327626 | I15: =315+G15 -> 317.89615
C16: Day 10 | G16: =E16+(F16*$O$3) -> 0 | H16: =G16/$O$9 -> 0 | I16: =315+G16 -> 315
C17: Day 11 | G17: =E17+(F17*$O$3) -> 0 | H17: =G17/$O$9 -> 0 | I17: =315+G17 -> 315
C18: Day 12 | G18: =E18+(F18*$O$3) -> 0 | H18: =G18/$O$9 -> 0 | I18: =315+G18 -> 315
C19: Day 13 | G19: =E19+(F19*$O$3) -> 0 | H19: =G19/$O$9 -> 0 | I19: =315+G19 -> 315
C20: Day 14 | G20: =E20+(F20*$O$3) -> 0 | H20: =G20/$O$9 -> 0 | I20: =315+G20 -> 315
C21: Day 15 | G21: =E21+(F21*$O$3) -> 0 | H21: =G21/$O$9 -> 0 | I21: =315+G21 -> 315
C22: Day 16 | F22: =1.43+1.22+2.02 -> 4.67 | G22: =E22+(F22*$O$3) -> 4.0984854 | H22: =G22/$O$9 -> 0.034427277 | I22: =315+G22 -> 319.09849
C23: Day 17 | G23: =E23+(F23*$O$3) -> 0 | H23: =G23/$O$9 -> 0 | I23: =315+G23 -> 315
C24: Day 18 | G24: =E24+(F24*$O$3) -> 0 | H24: =G24/$O$9 -> 0 | I24: =315+G24 -> 315
C25: Day 19 | G25: =E25+(F25*$O$3) -> 0 | H25: =G25/$O$9 -> 0 | I25: =315+G25 -> 315
C26: Day 20 | G26: =E26+(F26*$O$3) -> 0 | H26: =G26/$O$9 -> 0 | I26: =315+G26 -> 315
C27: Day 21 | G27: =E27+(F27*$O$3) -> 0 | H27: =G27/$O$9 -> 0 | I27: =315+G27 -> 315
C28: Day 22 | G28: =E28+(F28*$O$3) -> 0 | H28: =G28/$O$9 -> 0 | I28: =315+G28 -> 315
C29: Day 23 | G29: =E29+(F29*$O$3) -> 0 | H29: =G29/$O$9 -> 0 | I29: =315+G29 -> 315
C30: Day 24 | G30: =E30+(F30*$O$3) -> 0 | H30: =G30/$O$9 -> 0 | I30: =315+G30 -> 315
C31: Day 25 | G31: =E31+(F31*$O$3) -> 0 | H31: =G31/$O$9 -> 0 | I31: =315+G31 -> 315
C32: Day 26 | G32: =E32+(F32*$O$3) -> 0 | H32: =G32/$O$9 -> 0 | I32: =315+G32 -> 315
C33: Day 27 | G33: =E33+(F33*$O$3) -> 0 | H33: =G33/$O$9 -> 0 | I33: =315+G33 -> 315
C34: Day 28 | G34: =E34+(F34*$O$3) -> 0 | H34: =G34/$O$9 -> 0 | I34: =315+G34 -> 315
... C37: Day 31 | G37: =E37+(F37*$O$3) -> 0 | H37: =G37/$O$9 -> 0 | I37: =315+G37 -> 315

Sheet FEV
K2: Valor Conta | L2: EUR | M2: USD | N2: USD em EU
K3: Total | L3: =sum(E7:E37) -> 0 | M3: =sum(F7:F37) -> 65.8 | N3: =M3*Sumario!N4 -> 57.747396 | O3: =Sumario!N4 -> 0.87762
B4: FEV
B5: Posicao | C5: Data | D5: Preço Abertura | E5: Lucro EU | F5: Lucro USD | G5: Total EUR
H6: Goal
C7: Day 1 | G7: =E7+(F7*$O$3) -> 0 | H7: =G7/$O$9 -> 0 | I7: =315+G7 -> 315
C8: Day 2 | G8: =E8+(F8*$O$3) -> 0 | H8: =G8/$O$9 -> 0 | I8: =315+G8 -> 315 | N8: Goal | O8: 2500 | P8: =O8-Sumario!K8 -> 2439.1554
C9: Day 3 | F9: =4.06 -> 4.06 | G9: =E9+(F9*$O$3) -> 3.5631372 | H9: =G9/$O$9 -> 0.029930352 | I9: =315+G9 -> 318.56314 | L9: 6300 | N9: Goal Day | O9: =O8/21 -> 119.04762 | P9: =P8/O8 -> 0.97566215
C10: Day 4 | G10: =E10+(F10*$O$3) -> 0 | H10: =G10/$O$9 -> 0 | I10: =315+G10 -> 315 | L10: =L9+Sumario!K8 -> 6360.8446
C11: Day 5 | G11: =E11+(F11*$O$3) -> 0 | H11: =G11/$O$9 -> 0 | I11: =315+G11 -> 315
C12: Day 6 | F12: =0.91+0.33+1.52+0.57+0.63+1.39 -> 5.35 | G12: =E12+(F12*$O$3) -> 4.695267 | H12: =G12/$O$9 -> 0.039440243 | I12: =315+G12 -> 319.69527
C13: Day 7 | G13: =E13+(F13*$O$3) -> 0 | H13: =G13/$O$9 -> 0 | I13: =315+G13 -> 315
C14: Day 8 | G14: =E14+(F14*$O$3) -> 0 | H14: =G14/$O$9 -> 0 | I14: =315+G14 -> 315
C15: Day 9 | G15: =E15+(F15*$O$3) -> 0 | H15: =G15/$O$9 -> 0 | I15: =315+G15 -> 315
C16: Day 10 | F16: =4+5.48 -> 9.48 | G16: =E16+(F16*$O$3) -> 8.3198376 | H16: =G16/$O$9 -> 0.069886636 | I16: =315+G16 -> 323.31984
C17: Day 11 | G17: =E17+(F17*$O$3) -> 0 | H17: =G17/$O$9 -> 0 | I17: =315+G17 -> 315
C18: Day 12 | G18: =E18+(F18*$O$3) -> 0 | H18: =G18/$O$9 -> 0 | I18: =315+G18 -> 315
C19: Day 13 | G19: =E19+(F19*$O$3) -> 0 | H19: =G19/$O$9 -> 0 | I19: =315+G19 -> 315
C20: Day 14 | G20: =E20+(F20*$O$3) -> 0 | H20: =G20/$O$9 -> 0 | I20: =315+G20 -> 315
C21: Day 15 | G21: =E21+(F21*$O$3) -> 0 | H21: =G21/$O$9 -> 0 | I21: =315+G21 -> 315
C22: Day 16 | G22: =E22+(F22*$O$3) -> 0 | H22: =G22/$O$9 -> 0 | I22: =315+G22 -> 315
C23: Day 17 | G23: =E23+(F23*$O$3) -> 0 | H23: =G23/$O$9 -> 0 | I23: =315+G23 -> 315
C24: Day 18 | G24: =E24+(F24*$O$3) -> 0 | H24: =G24/$O$9 -> 0 | I24: =315+G24 -> 315
C25: Day 19 | F25: =3.36+1.72 -> 5.08 | G25: =E25+(F25*$O$3) -> 4.4583096 | H25: =G25/$O$9 -> 0.037449801 | I25: =315+G25 -> 319.45831
C26: Day 20 | G26: =E26+(F26*$O$3) -> 0 | H26: =G26/$O$9 -> 0 | I26: =315+G26 -> 315
C27: Day 21 | G27: =E27+(F27*$O$3) -> 0 | H27: =G27/$O$9 -> 0 | I27: =315+G27 -> 315
C28: Day 22 | G28: =E28+(F28*$O$3) -> 0 | H28: =G28/$O$9 -> 0 | I28: =315+G28 -> 315
C29: Day 23 | G29: =E29+(F29*$O$3) -> 0 | H29: =G29/$O$9 -> 0 | I29: =315+G29 -> 315
C30: Day 24 | G30: =E30+(F30*$O$3) -> 0 | H30: =G30/$O$9 -> 0 | I30: =315+G30 -> 315
C31: Day 25 | G31: =E31+(F31*$O$3) -> 0 | H31: =G31/$O$9 -> 0 | I31: =315+G31 -> 315
C32: Day 26 | F32: =16.07+14.62+11.14 -> 41.83 | G32: =E32+(F32*$O$3) -> 36.710845 | H32: =G32/$O$9 -> 0.30837109 | I32: =315+G32 -> 351.71084
C33: Day 27 | G33: =E33+(F33*$O$3) -> 0 | H33: =G33/$O$9 -> 0 | I33: =315+G33 -> 315
C34: Day 28 | G34: =E34+(F34*$O$3) -> 0 | H34: =G34/$O$9 -> 0 | I34: =315+G34 -> 315
C35: Day 29 | G35: =E35+(F35*$O$3) -> 0 | H35: =G35/$O$9 -> 0 | I35: =315+G35 -> 315
C36: Day 30 | G36: =E36+(F36*$O$3) -> 0 | H36: =G36/$O$9 -> 0 | I36: =315+G36 -> 315
C37: Day 31 | G37: =E37+(F37*$O$3) -> 0 | H37: =G37/$O$9 -> 0 | I37: =315+G37 -> 315

Sheet MAR
K2: Valor Conta | L2: EUR | M2: USD | N2: USD em EU
K3: Total | L3: =sum(E7:E37) -> 0 | M3: =sum(F7:F37) -> 297.24 | N3: =M3*Sumario!N4 -> 260.86377 | O3: =Sumario!N4 -> 0.87762
B4: MAR
B5: Posicao | C5: Data | D5: Preço Abertura | E5: Lucro EU | F5: Lucro USD | G5: Total EUR
H6: Goal
C7: Day 1 | G7: =E7+(F7*$O$3) -> 0 | H7: =G7/$O$9 -> 0 | I7: =315+G7 -> 315
C8: Day 2 | F8: =20.55+1.25 -> 21.8 | G8: =E8+(F8*$O$3) -> 19.132116 | H8: =G8/$O$9 -> 0.16070977 | I8: =315+G8 -> 334.13212 | N8: Goal | O8: 2500 | P8: =O8-Sumario!K9 -> 2235.506
C9: Day 3 | F9: =7.44+1.37 -> 8.81 | G9: =E9+(F9*$O$3) -> 7.7318322 | H9: =G9/$O$9 -> 0.06494739 | I9: =315+G9 -> 322.73183 | L9: 6930 | N9: Goal Day | O9: =O8/21 -> 119.04762 | P9: =P8/O8 -> 0.8942024
C10: Day 4 | F10: =5.96+5.23+6.43 -> 17.62 | G10: =E10+(F10*$O$3) -> 15.463664 | H10: =G10/$O$9 -> 0.12989478 | I10: =315+G10 -> 330.46366 | L10: =L9+Sumario!K9 -> 7194.494
C11: Day 5 | F11: =7.5 -> 7.5 | G11: =E11+(F11*$O$3) -> 6.58215 | H11: =G11/$O$9 -> 0.05529006 | I11: =315+G11 -> 321.58215
C12: Day 6 | F12: =21.87+18.23 -> 40.1 | G12: =E12+(F12*$O$3) -> 35.192562 | H12: =G12/$O$9 -> 0.29561752 | I12: =315+G12 -> 350.19256
C13: Day 7 | G13: =E13+(F13*$O$3) -> 0 | H13: =G13/$O$9 -> 0 | I13: =315+G13 -> 315
C14: Day 8 | G14: =E14+(F14*$O$3) -> 0 | H14: =G14/$O$9 -> 0 | I14: =315+G14 -> 315
C15: Day 9 | G15: =E15+(F15*$O$3) -> 0 | H15: =G15/$O$9 -> 0 | I15: =315+G15 -> 315
C16: Day 10 | F16: =25.88+19.05+4.77+13.03 -> 62.73 | G16: =E16+(F16*$O$3) -> 55.053103 | H16: =G16/$O$9 -> 0.46244606 | I16: =315+G16 -> 370.0531
C17: Day 11 | G17: =E17+(F17*$O$3) -> 0 | H17: =G17/$O$9 -> 0 | I17: =315+G17 -> 315
C18: Day 12 | G18: =E18+(F18*$O$3) -> 0 | H18: =G18/$O$9 -> 0 | I18: =315+G18 -> 315
C19: Day 13 | F19: =9.1+0.97+9.12+0.96+4.42+5.04 -> 29.61 | G19: =E19+(F19*$O$3) -> 25.986328 | H19: =G19/$O$9 -> 0.21828516 | I19: =315+G19 -> 340.98633
C20: Day 14 | G20: =E20+(F20*$O$3) -> 0 | H20: =G20/$O$9 -> 0 | I20: =315+G20 -> 315
C21: Day 15 | G21: =E21+(F21*$O$3) -> 0 | H21: =G21/$O$9 -> 0 | I21: =315+G21 -> 315
C22: Day 16 | F22: =3.11 -> 3.11 | G22: =E22+(F22*$O$3) -> 2.7293982 | H22: =G22/$O$9 -> 0.022926945 | I22: =315+G22 -> 317.7294
C23: Day 17 | F23: =7.49+2.49 -> 9.98 | G23: =E23+(F23*$O$3) -> 8.7586476 | H23: =G23/$O$9 -> 0.07357264 | I23: =315+G23 -> 323.75865
C24: Day 18 | F24: =4.66+2.22 -> 6.88 | G24: =E24+(F24*$O$3) -> 6.0380256 | H24: =G24/$O$9 -> 0.050719415 | I24: =315+G24 -> 321.03803
C25: Day 19 | G25: =E25+(F25*$O$3) -> 0 | H25: =G25/$O$9 -> 0 | I25: =315+G25 -> 315
C26: Day 20 | G26: =E26+(F26*$O$3) -> 0 | H26: =G26/$O$9 -> 0 | I26: =315+G26 -> 315
C27: Day 21 | G27: =E27+(F27*$O$3) -> 0 | H27: =G27/$O$9 -> 0 | I27: =315+G27 -> 315
C28: Day 22 | G28: =E28+(F28*$O$3) -> 0 | H28: =G28/$O$9 -> 0 | I28: =315+G28 -> 315
C29: Day 23 | G29: =E29+(F29*$O$3) -> 0 | H29: =G29/$O$9 -> 0 | I29: =315+G29 -> 315
C30: Day 24 | F30: =35.7 -> 35.7 | G30: =E30+(F30*$O$3) -> 31.331034 | H30: =G30/$O$9 -> 0.26318069 | I30: =315+G30 -> 346.33103
C31: Day 25 | G31: =E31+(F31*$O$3) -> 0 | H31: =G31/$O$9 -> 0 | I31: =315+G31 -> 315
C32: Day 26 | G32: =E32+(F32*$O$3) -> 0 | H32: =G32/$O$9 -> 0 | I32: =315+G32 -> 315
C33: Day 27 | G33: =E33+(F33*$O$3) -> 0 | H33: =G33/$O$9 -> 0 | I33: =315+G33 -> 315
C34: Day 28 | G34: =E34+(F34*$O$3) -> 0 | H34: =G34/$O$9 -> 0 | I34: =315+G34 -> 315
C35: Day 29 | G35: =E35+(F35*$O$3) -> 0 | H35: =G35/$O$9 -> 0 | I35: =315+G35 -> 315
C36: Day 30 | G36: =E36+(F36*$O$3) -> 0 | H36: =G36/$O$9 -> 0 | I36: =315+G36 -> 315
C37: Day 31 | F37: =38.55+8.11+6.74 -> 53.4 | G37: =E37+(F37*$O$3) -> 46.864908 | H37: =G37/$O$9 -> 0.39366523 | I37: =315+G37 -> 361.86491

Sheet ABR
K2: Valor Conta | L2: EUR | M2: USD | N2: USD em EU
K3: Total | L3: =sum(E7:E37) -> 11.31 | M3: =sum(F7:F37) -> 388.56 | N3: =M3*Sumario!N4 -> 341.00803 | O3: =Sumario!N4 -> 0.87762
B4: ABR
B5: Posicao | C5: Data | D5: Preço Abertura | E5: Lucro EU | F5: Lucro USD | G5: Total EUR
H6: Goal
C7: Day 1 | F7: =13.05+2.54 -> 15.59 | G7: =E7+(F7*$O$3) -> 13.682096 | H7: =G7/$O$9 -> 0.1149296 | I7: =315+G7 -> 328.6821
C8: Day 2 | F8: =5.72+3.96+9.37+1.37+3.16 -> 23.58 | G8: =E8+(F8*$O$3) -> 20.69428 | H8: =G8/$O$9 -> 0.17383195 | I8: =315+G8 -> 335.69428 | N8: Goal | O8: 2500 | P8: =O8-Sumario!K10 -> 2125.4604
C9: Day 3 | G9: =E9+(F9*$O$3) -> 0 | H9: =G9/$O$9 -> 0 | I9: =315+G9 -> 315 | L9: 6615 | N9: Goal Day | O9: =O8/21 -> 119.04762 | P9: =P8/O8 -> 0.85018415
C10: Day 4 | G10: =E10+(F10*$O$3) -> 0 | H10: =G10/$O$9 -> 0 | I10: =315+G10 -> 315 | L10: =L9+Sumario!K10 -> 6989.5396
C11: Day 5 | G11: =E11+(F11*$O$3) -> 0 | H11: =G11/$O$9 -> 0 | I11: =315+G11 -> 315
C12: Day 6 | F12: =0.6+6.82+1.43+3.06+2.69+2.18+12.21+1.31+1.44+4.05+0.57+0.87+2.4 -> 39.63 | G12: =E12+(F12*$O$3) -> 34.780081 | H12: =G12/$O$9 -> 0.29215268 | I12: =315+G12 -> 349.78008
C13: Day 7 | F13: =3.94+1.5+0.74+6.7+2+1.5+2.46+2.25+1.36 -> 22.45 | G13: =E13+(F13*$O$3) -> 19.702569 | H13: =G13/$O$9 -> 0.16550158 | I13: =315+G13 -> 334.70257
C14: Day 8 | E14: =2.15 -> 2.15 | F14: =1.51+6.28+8.74+3.85+0.96+3.34+3.7+0.13+3.72+0.11+2.59+0.03+4.78+3.65+3.28 -> 46.67 | G14: =E14+(F14*$O$3) -> 43.108525 | H14: =G14/$O$9 -> 0.36211161 | I14: =315+G14 -> 358.10853
C15: Day 9 | F15: =5.1+3.9+11.35+4.63+0.58+0.05+0.62 -> 26.23 | G15: =E15+(F15*$O$3) -> 23.019973 | H15: =G15/$O$9 -> 0.19336777 | I15: =315+G15 -> 338.01997
C16: Day 10 | F16: =1.98+2.4 -> 4.38 | G16: =E16+(F16*$O$3) -> 3.8439756 | H16: =G16/$O$9 -> 0.032289395 | I16: =315+G16 -> 318.84398
C17: Day 11 | G17: =E17+(F17*$O$3) -> 0 | H17: =G17/$O$9 -> 0 | I17: =315+G17 -> 315
C18: Day 12 | G18: =E18+(F18*$O$3) -> 0 | H18: =G18/$O$9 -> 0 | I18: =315+G18 -> 315
C19: Day 13 | F19: =2.46+2.1+3.1+12.32+1.3+7.05+6.59+3.78 -> 38.7 | G19: =E19+(F19*$O$3) -> 33.963894 | H19: =G19/$O$9 -> 0.28529671 | I19: =315+G19 -> 348.96389
C20: Day 14 | F20: =2.41+2.8+14.43 -> 19.64 | G20: =E20+(F20*$O$3) -> 17.236457 | H20: =G20/$O$9 -> 0.14478624 | I20: =315+G20 -> 332.23646
C21: Day 15 | F21: =8.73+5.49+12.21+8.21 -> 34.64 | G21: =E21+(F21*$O$3) -> 30.400757 | H21: =G21/$O$9 -> 0.25536636 | I21: =315+G21 -> 345.40076
C22: Day 16 | F22: =5+34.8+9.82+12.38 -> 62 | G22: =E22+(F22*$O$3) -> 54.41244 | H22: =G22/$O$9 -> 0.4570645 | I22: =315+G22 -> 369.41244
C23: Day 17 | F23: =3.84+5.1+2.64 -> 11.58 | G23: =E23+(F23*$O$3) -> 10.16284 | H23: =G23/$O$9 -> 0.085367853 | I23: =315+G23 -> 325.16284
C24: Day 18 | G24: =E24+(F24*$O$3) -> 0 | H24: =G24/$O$9 -> 0 | I24: =315+G24 -> 315
C25: Day 19 | G25: =E25+(F25*$O$3) -> 0 | H25: =G25/$O$9 -> 0 | I25: =315+G25 -> 315
C26: Day 20 | F26: =9.1+0.48+0.5+0.5+1.18 -> 11.76 | G26: =E26+(F26*$O$3) -> 10.320811 | H26: =G26/$O$9 -> 0.086694814 | I26: =315+G26 -> 325.32081
C27: Day 21 | F27: =0.82+0.2+8.6+8.6+2.35 -> 20.57 | G27: =E27+(F27*$O$3) -> 18.052643 | H27: =G27/$O$9 -> 0.1516422 | I27: =315+G27 -> 333.05264
C28: Day 22 | F28: =4.22 -> 4.22 | G28: =E28+(F28*$O$3) -> 3.7035564 | H28: =G28/$O$9 -> 0.031109874 | I28: =315+G28 -> 318.70356
C29: Day 23 | G29: =E29+(F29*$O$3) -> 0 | H29: =G29/$O$9 -> 0 | I29: =315+G29 -> 315
C30: Day 24 | G30: =E30+(F30*$O$3) -> 0 | H30: =G30/$O$9 -> 0 | I30: =315+G30 -> 315
C31: Day 25 | G31: =E31+(F31*$O$3) -> 0 | H31: =G31/$O$9 -> 0 | I31: =315+G31 -> 315
C32: Day 26 | G32: =E32+(F32*$O$3) -> 0 | H32: =G32/$O$9 -> 0 | I32: =315+G32 -> 315
C33: Day 27 | E33: =0.22+0.76+6.09 -> 7.07 | G33: =E33+(F33*$O$3) -> 7.07 | H33: =G33/$O$9 -> 0.059388 | I33: =315+G33 -> 322.07
C34: Day 28 | G34: =E34+(F34*$O$3) -> 0 | H34: =G34/$O$9 -> 0 | I34: =315+G34 -> 315
C35: Day 29 | G35: =E35+(F35*$O$3) -> 0 | H35: =G35/$O$9 -> 0 | I35: =315+G35 -> 315
C36: Day 30 | E36: =2.09 -> 2.09 | F36: =5.26+1.66 -> 6.92 | G36: =E36+(F36*$O$3) -> 8.1631304 | H36: =G36/$O$9 -> 0.068570295 | I36: =315+G36 -> 323.16313
C37: Day 31 | G37: =E37+(F37*$O$3) -> 0 | H37: =G37/$O$9 -> 0 | I37: =315+G37 -> 315

Sheet MAI
K2: Valor Conta | L2: EUR | M2: USD | N2: USD em EU
K3: Total | L3: =sum(E7:E37) -> 0 | M3: =sum(F7:F37) -> 606.31 | N3: =M3*Sumario!N4 -> 532.10978 | O3: =Sumario!N4 -> 0.87762
B4: MAI
B5: Posicao | C5: Data | D5: Preço Abertura | E5: Lucro EU | F5: Lucro USD | G5: Total EUR
H6: Goal
C7: Day 1 | F7: =2.61+2.68+4.62 -> 9.91 | G7: =E7+(F7*$O$3) -> 8.6972142 | H7: =G7/$O$9 -> 0.073056599 | I7: =315+G7 -> 323.69721
C8: Day 2 | G8: =E8+(F8*$O$3) -> 0 | H8: =G8/$O$9 -> 0 | I8: =315+G8 -> 315 | N8: Goal | O8: 2500 | P8: =O8-Sumario!K11 -> 1957.8545
C9: Day 3 | G9: =E9+(F9*$O$3) -> 0 | H9: =G9/$O$9 -> 0 | I9: =315+G9 -> 315 | L9: 6300 | N9: Goal Day | O9: =O8/21 -> 119.04762 | P9: =P8/O8 -> 0.78314178
C10: Day 4 | F10: =4.17+19.3+9.6 -> 33.07 | G10: =E10+(F10*$O$3) -> 29.022893 | H10: =G10/$O$9 -> 0.2437923 | I10: =315+G10 -> 344.02289 | L10: =L9+Sumario!K11 -> 6842.1456
C11: Day 5 | G11: =E11+(F11*$O$3) -> 0 | H11: =G11/$O$9 -> 0 | I11: =315+G11 -> 315
C12: Day 6 | F12: =18.98+3.03+5.1 -> 27.11 | G12: =E12+(F12*$O$3) -> 23.792278 | H12: =G12/$O$9 -> 0.19985514 | I12: =315+G12 -> 338.79228
C13: Day 7 | F13: =7.6+8.87+7.74+9.36+4.68+8.11+4.52+4.86 -> 55.74 | G13: =E13+(F13*$O$3) -> 48.918539 | H13: =G13/$O$9 -> 0.41091573 | I13: =315+G13 -> 363.91854
C14: Day 8 | F14: =27.52 -> 27.52 | G14: =E14+(F14*$O$3) -> 24.152102 | H14: =G14/$O$9 -> 0.20287766 | I14: =315+G14 -> 339.1521
C15: Day 9 | G15: =E15+(F15*$O$3) -> 0 | H15: =G15/$O$9 -> 0 | I15: =315+G15 -> 315
C16: Day 10 | G16: =E16+(F16*$O$3) -> 0 | H16: =G16/$O$9 -> 0 | I16: =315+G16 -> 315
C17: Day 11 | F17: =111.5+8.89+22.35 -> 142.74 | G17: =E17+(F17*$O$3) -> 125.27148 | H17: =G17/$O$9 -> 1.0522804 | I17: =315+G17 -> 440.27148
C18: Day 12 | F18: =6+4.79+1.07+1.16+10.25+7.67+2.11 -> 33.05 | G18: =E18+(F18*$O$3) -> 29.005341 | H18: =G18/$O$9 -> 0.24364486 | I18: =315+G18 -> 344.00534
C19: Day 13 | F19: =0.44+1.16+7.99+16.2 -> 25.79 | G19: =E19+(F19*$O$3) -> 22.63382 | H19: =G19/$O$9 -> 0.19012409 | I19: =315+G19 -> 337.63382
C20: Day 14 | F20: =4.42+7.84+6.07+11.4 -> 29.73 | G20: =E20+(F20*$O$3) -> 26.091643 | H20: =G20/$O$9 -> 0.2191698 | I20: =315+G20 -> 341.09164
C21: Day 15 | F21: =12.1+13.45+1.1+2.52+0.48 -> 29.65 | G21: =E21+(F21*$O$3) -> 26.021433 | H21: =G21/$O$9 -> 0.21858004 | I21: =315+G21 -> 341.02143
C22: Day 16 | G22: =E22+(F22*$O$3) -> 0 | H22: =G22/$O$9 -> 0 | I22: =315+G22 -> 315
C23: Day 17 | G23: =E23+(F23*$O$3) -> 0 | H23: =G23/$O$9 -> 0 | I23: =315+G23 -> 315
C24: Day 18 | F24: =9.19 -> 9.19 | G24: =E24+(F24*$O$3) -> 8.0653278 | H24: =G24/$O$9 -> 0.067748754 | I24: =315+G24 -> 323.06533
C25: Day 19 | G25: =E25+(F25*$O$3) -> 0 | H25: =G25/$O$9 -> 0 | I25: =315+G25 -> 315
C26: Day 20 | G26: =E26+(F26*$O$3) -> 0 | H26: =G26/$O$9 -> 0 | I26: =315+G26 -> 315
C27: Day 21 | F27: =52.14 -> 52.14 | G27: =E27+(F27*$O$3) -> 45.759107 | H27: =G27/$O$9 -> 0.3843765 | I27: =315+G27 -> 360.75911
C28: Day 22 | F28: =7.93+15.81 -> 23.74 | G28: =E28+(F28*$O$3) -> 20.834699 | H28: =G28/$O$9 -> 0.17501147 | I28: =315+G28 -> 335.8347
C29: Day 23 | G29: =E29+(F29*$O$3) -> 0 | H29: =G29/$O$9 -> 0 | I29: =315+G29 -> 315
C30: Day 24 | G30: =E30+(F30*$O$3) -> 0 | H30: =G30/$O$9 -> 0 | I30: =315+G30 -> 315
C31: Day 25 | G31: =E31+(F31*$O$3) -> 0 | H31: =G31/$O$9 -> 0 | I31: =315+G31 -> 315
C32: Day 26 | F32: =18.68 -> 18.68 | G32: =E32+(F32*$O$3) -> 16.393942 | H32: =G32/$O$9 -> 0.13770911 | I32: =315+G32 -> 331.39394
C33: Day 27 | G33: =E33+(F33*$O$3) -> 0 | H33: =G33/$O$9 -> 0 | I33: =315+G33 -> 315
C34: Day 28 | F34: =8.34+7.76+6.34+7.2+12.57+7.06+14.54 -> 63.81 | G34: =E34+(F34*$O$3) -> 56.000932 | H34: =G34/$O$9 -> 0.47040783 | I34: =315+G34 -> 371.00093
C35: Day 29 | F35: =2.16+3.05+2.22+1.41+8.32+1.94+5.34 -> 24.44 | G35: =E35+(F35*$O$3) -> 21.449033 | H35: =G35/$O$9 -> 0.18017188 | I35: =315+G35 -> 336.44903
C36: Day 30 | G36: =E36+(F36*$O$3) -> 0 | H36: =G36/$O$9 -> 0 | I36: =315+G36 -> 315
C37: Day 31 | G37: =E37+(F37*$O$3) -> 0 | H37: =G37/$O$9 -> 0 | I37: =315+G37 -> 315

Sheet JUN
K2: Valor Conta | L2: EUR | M2: USD | N2: USD em EU
K3: Total | L3: =sum(E7:E37) -> 0 | M3: =sum(F7:F37) -> 127.55 | N3: =M3*Sumario!N4 -> 111.94043 | O3: =Sumario!N4 -> 0.87762
B4: JUN
B5: Posicao | C5: Data | D5: Preço Abertura | E5: Lucro EU | F5: Lucro USD | G5: Total EUR
H6: Goal
C7: Day 1 | F7: =6.02+14.31+8.88+1.5 -> 30.71 | G7: =E7+(F7*$O$3) -> 26.95171 | H7: =G7/$O$9 -> 0.22639437 | I7: =315+G7 -> 341.95171
C8: Day 2 | G8: =E8+(F8*$O$3) -> 0 | H8: =G8/$O$9 -> 0 | I8: =315+G8 -> 315 | N8: Goal | O8: 2500 | P8: =O8-Sumario!K12 -> 2381.7577
C9: Day 3 | G9: =E9+(F9*$O$3) -> 0 | H9: =G9/$O$9 -> 0 | I9: =315+G9 -> 315 | L9: 7245 | N9: Goal Day | O9: =O8/21 -> 119.04762 | P9: =P8/O8 -> 0.95270309
C10: Day 4 | G10: =E10+(F10*$O$3) -> 0 | H10: =G10/$O$9 -> 0 | I10: =315+G10 -> 315 | L10: =L9+Sumario!K12 -> 7363.2423
C11: Day 5 | G11: =E11+(F11*$O$3) -> 0 | H11: =G11/$O$9 -> 0 | I11: =315+G11 -> 315
C12: Day 6 | G12: =E12+(F12*$O$3) -> 0 | H12: =G12/$O$9 -> 0 | I12: =315+G12 -> 315
C13: Day 7 | G13: =E13+(F13*$O$3) -> 0 | H13: =G13/$O$9 -> 0 | I13: =315+G13 -> 315
C14: Day 8 | G14: =E14+(F14*$O$3) -> 0 | H14: =G14/$O$9 -> 0 | I14: =315+G14 -> 315
C15: Day 9 | F15: =11.4 -> 11.4 | G15: =E15+(F15*$O$3) -> 10.004868 | H15: =G15/$O$9 -> 0.084040891 | I15: =315+G15 -> 325.00487
C16: Day 10 | F16: =28.49 -> 28.49 | G16: =E16+(F16*$O$3) -> 25.003394 | H16: =G16/$O$9 -> 0.21002851 | I16: =315+G16 -> 340.00339
C17: Day 11 | G17: =E17+(F17*$O$3) -> 0 | H17: =G17/$O$9 -> 0 | I17: =315+G17 -> 315
C18: Day 12 | F18: =9.78+1.97 -> 11.75 | G18: =E18+(F18*$O$3) -> 10.312035 | H18: =G18/$O$9 -> 0.086621094 | I18: =315+G18 -> 325.31203
C19: Day 13 | G19: =E19+(F19*$O$3) -> 0 | H19: =G19/$O$9 -> 0 | I19: =315+G19 -> 315
C20: Day 14 | G20: =E20+(F20*$O$3) -> 0 | H20: =G20/$O$9 -> 0 | I20: =315+G20 -> 315
C21: Day 15 | F21: =3.3+7.01 -> 10.31 | G21: =E21+(F21*$O$3) -> 9.0482622 | H21: =G21/$O$9 -> 0.076005402 | I21: =315+G21 -> 324.04826
C22: Day 16 | G22: =E22+(F22*$O$3) -> 0 | H22: =G22/$O$9 -> 0 | I22: =315+G22 -> 315
C23: Day 17 | F23: =7.42+20.45+3.9+0.76+2.36 -> 34.89 | G23: =E23+(F23*$O$3) -> 30.620162 | H23: =G23/$O$9 -> 0.25720936 | I23: =315+G23 -> 345.62016
C24: Day 18 | G24: =E24+(F24*$O$3) -> 0 | H24: =G24/$O$9 -> 0 | I24: =315+G24 -> 315
C25: Day 19 | G25: =E25+(F25*$O$3) -> 0 | H25: =G25/$O$9 -> 0 | I25: =315+G25 -> 315
C26: Day 20 | G26: =E26+(F26*$O$3) -> 0 | H26: =G26/$O$9 -> 0 | I26: =315+G26 -> 315
C27: Day 21 | G27: =E27+(F27*$O$3) -> 0 | H27: =G27/$O$9 -> 0 | I27: =315+G27 -> 315
C28: Day 22 | G28: =E28+(F28*$O$3) -> 0 | H28: =G28/$O$9 -> 0 | I28: =315+G28 -> 315
C29: Day 23 | G29: =E29+(F29*$O$3) -> 0 | H29: =G29/$O$9 -> 0 | I29: =315+G29 -> 315
C30: Day 24 | G30: =E30+(F30*$O$3) -> 0 | H30: =G30/$O$9 -> 0 | I30: =315+G30 -> 315
C31: Day 25 | G31: =E31+(F31*$O$3) -> 0 | H31: =G31/$O$9 -> 0 | I31: =315+G31 -> 315
C32: Day 26 | G32: =E32+(F32*$O$3) -> 0 | H32: =G32/$O$9 -> 0 | I32: =315+G32 -> 315
C33: Day 27 | G33: =E33+(F33*$O$3) -> 0 | H33: =G33/$O$9 -> 0 | I33: =315+G33 -> 315
C34: Day 28 | G34: =E34+(F34*$O$3) -> 0 | H34: =G34/$O$9 -> 0 | I34: =315+G34 -> 315
C35: Day 29 | G35: =E35+(F35*$O$3) -> 0 | H35: =G35/$O$9 -> 0 | I35: =315+G35 -> 315
... C37: Day 31 | G37: =E37+(F37*$O$3) -> 0 | H37: =G37/$O$9 -> 0 | I37: =315+G37 -> 315

Sheet JUL
K2: Valor Conta | L2: EUR | M2: USD | N2: USD em EU
K3: Total | L3: =sum(E7:E37) -> 0 | M3: =sum(F7:F37) -> -429.78 | N3: =M3*Sumario!N4 -> -377.18352 | O3: =Sumario!N4 -> 0.87762
B4: JUL
B5: Posicao | C5: Data | D5: Preço Abertura | E5: Lucro EU | F5: Lucro USD | G5: Total EUR
H6: Goal
C7: Day 1 | G7: =E7+(F7*$O$3) -> 0 | H7: =G7/$O$9 -> 0 | I7: =315+G7 -> 315
C8: Day 2 | G8: =E8+(F8*$O$3) -> 0 | H8: =G8/$O$9 -> 0 | I8: =315+G8 -> 315 | N8: Goal | O8: 2500 | P8: =O8-Sumario!K13 -> 2844.36
C9: Day 3 | G9: =E9+(F9*$O$3) -> 0 | H9: =G9/$O$9 -> 0 | I9: =315+G9 -> 315 | L9: 7245 | N9: Goal Day | O9: =O8/21 -> 119.04762 | P9: =P8/O8 -> 1.137744
C10: Day 4 | G10: =E10+(F10*$O$3) -> 0 | H10: =G10/$O$9 -> 0 | I10: =315+G10 -> 315 | L10: =L9+Sumario!K13 -> 6900.64
C11: Day 5 | G11: =E11+(F11*$O$3) -> 0 | H11: =G11/$O$9 -> 0 | I11: =315+G11 -> 315
C12: Day 6 | F12: =31.39+10.97 -> 42.36 | G12: =E12+(F12*$O$3) -> 37.175983 | H12: =G12/$O$9 -> 0.31227826 | I12: =315+G12 -> 352.17598
C13: Day 7 | G13: =E13+(F13*$O$3) -> 0 | H13: =G13/$O$9 -> 0 | I13: =315+G13 -> 315
C14: Day 8 | G14: =E14+(F14*$O$3) -> 0 | H14: =G14/$O$9 -> 0 | I14: =315+G14 -> 315
C15: Day 9 | G15: =E15+(F15*$O$3) -> 0 | H15: =G15/$O$9 -> 0 | I15: =315+G15 -> 315
C16: Day 10 | G16: =E16+(F16*$O$3) -> 0 | H16: =G16/$O$9 -> 0 | I16: =315+G16 -> 315
C17: Day 11 | G17: =E17+(F17*$O$3) -> 0 | H17: =G17/$O$9 -> 0 | I17: =315+G17 -> 315
C18: Day 12 | G18: =E18+(F18*$O$3) -> 0 | H18: =G18/$O$9 -> 0 | I18: =315+G18 -> 315
C19: Day 13 | G19: =E19+(F19*$O$3) -> 0 | H19: =G19/$O$9 -> 0 | I19: =315+G19 -> 315
C20: Day 14 | G20: =E20+(F20*$O$3) -> 0 | H20: =G20/$O$9 -> 0 | I20: =315+G20 -> 315
C21: Day 15 | G21: =E21+(F21*$O$3) -> 0 | H21: =G21/$O$9 -> 0 | I21: =315+G21 -> 315
C22: Day 16 | F22: =3.95-37.98 -> -34.03 | G22: =E22+(F22*$O$3) -> -29.865409 | H22: =G22/$O$9 -> -0.25086943 | I22: =315+G22 -> 285.13459
C23: Day 17 | F23: =20.83+10.13+4.26-336.26 -> -301.04 | G23: =E23+(F23*$O$3) -> -264.19872 | H23: =G23/$O$9 -> -2.2192693 | I23: =315+G23 -> 50.801275
C24: Day 18 | G24: =E24+(F24*$O$3) -> 0 | H24: =G24/$O$9 -> 0 | I24: =315+G24 -> 315
C25: Day 19 | G25: =E25+(F25*$O$3) -> 0 | H25: =G25/$O$9 -> 0 | I25: =315+G25 -> 315
C26: Day 20 | G26: =E26+(F26*$O$3) -> 0 | H26: =G26/$O$9 -> 0 | I26: =315+G26 -> 315
C27: Day 21 | F27: =-31.29-41.74-42.07 -> -115.1 | G27: =E27+(F27*$O$3) -> -101.01406 | H27: =G27/$O$9 -> -0.84851812 | I27: =315+G27 -> 213.98594
C28: Day 22 | F28: =-20.04-53.81-0.67 -> -74.52 | G28: =E28+(F28*$O$3) -> -65.400242 | H28: =G28/$O$9 -> -0.54936204 | I28: =315+G28 -> 249.59976
C29: Day 23 | G29: =E29+(F29*$O$3) -> 0 | H29: =G29/$O$9 -> 0 | I29: =315+G29 -> 315
C30: Day 24 | F30: =2.73 -> 2.73 | G30: =E30+(F30*$O$3) -> 2.3959026 | H30: =G30/$O$9 -> 0.020125582 | I30: =315+G30 -> 317.3959
C31: Day 25 | G31: =E31+(F31*$O$3) -> 0 | H31: =G31/$O$9 -> 0 | I31: =315+G31 -> 315
C32: Day 26 | G32: =E32+(F32*$O$3) -> 0 | H32: =G32/$O$9 -> 0 | I32: =315+G32 -> 315
C33: Day 27 | G33: =E33+(F33*$O$3) -> 0 | H33: =G33/$O$9 -> 0 | I33: =315+G33 -> 315
C34: Day 28 | F34: =-48.16-24.64 -> -72.8 | G34: =E34+(F34*$O$3) -> -63.890736 | H34: =G34/$O$9 -> -0.53668218 | I34: =315+G34 -> 251.10926
C35: Day 29 | F35: =-45.15+79.7 -> 34.55 | G35: =E35+(F35*$O$3) -> 30.321771 | H35: =G35/$O$9 -> 0.25470288 | I35: =315+G35 -> 345.32177
C36: Day 30 | G36: =E36+(F36*$O$3) -> 0 | H36: =G36/$O$9 -> 0 | I36: =315+G36 -> 315
C37: Day 31 | F37: =88.07 -> 88.07 | G37: =E37+(F37*$O$3) -> 77.291993 | H37: =G37/$O$9 -> 0.64925274 | I37: =315+G37 -> 392.29199

Sheet AGO
K2: Valor Conta | L2: EUR | M2: USD | N2: USD em EU
K3: Total | L3: =sum(E7:E37) -> 76.77 | M3: =sum(F7:F37) -> -1446.55 | N3: =M3*Sumario!N4 -> -1269.5212 | O3: =Sumario!N4 -> 0.87762
B4: AGO
B5: Posicao | C5: Data | D5: Preço Abertura | E5: Lucro EU | F5: Lucro USD | G5: Total EUR
H6: Goal
C7: Day 1 | G7: =E7+(F7*$O$3) -> 0 | H7: =G7/$O$9 -> 0 | I7: =315+G7 -> 315
C8: Day 2 | G8: =E8+(F8*$O$3) -> 0 | H8: =G8/$O$9 -> 0 | I8: =315+G8 -> 315 | N8: Goal | O8: 1000 | P8: =O8-Sumario!K14 -> 2187.0243
C9: Day 3 | G9: =E9+(F9*$O$3) -> 0 | H9: =G9/$O$9 -> 0 | I9: =315+G9 -> 315 | L9: 6615 | N9: Goal Day | O9: =O8/21 -> 47.619048 | P9: =P8/O8 -> 2.1870243
C10: Day 4 | F10: =9.43+0.27+6.82+0.08+0.06+185.87 -> 202.53 | G10: =E10+(F10*$O$3) -> 177.74438 | H10: =G10/$O$9 -> 3.732632 | I10: =315+G10 -> 492.74438 | L10: =L9+Sumario!K14 -> 5427.9757
C11: Day 5 | F11: =-20.95-16.82-3.44 -> -41.21 | G11: =E11+(F11*$O$3) -> -36.16672 | H11: =G11/$O$9 -> -0.75950112 | I11: =315+G11 -> 278.83328
C12: Day 6 | F12: =-10.15-637.02+2.69+3.74+3.74+3.74+3.91+24.73 -> -604.62 | G12: =E12+(F12*$O$3) -> -530.6266 | H12: =G12/$O$9 -> -11.143159 | I12: =315+G12 -> -215.6266
C13: Day 7 | G13: =E13+(F13*$O$3) -> 0 | H13: =G13/$O$9 -> 0 | I13: =315+G13 -> 315
C14: Day 8 | G14: =E14+(F14*$O$3) -> 0 | H14: =G14/$O$9 -> 0 | I14: =315+G14 -> 315
C15: Day 9 | G15: =E15+(F15*$O$3) -> 0 | H15: =G15/$O$9 -> 0 | I15: =315+G15 -> 315
C16: Day 10 | F16: =15.46+54.92-31.81 -> 38.57 | G16: =E16+(F16*$O$3) -> 33.849803 | H16: =G16/$O$9 -> 0.71084587 | I16: =315+G16 -> 348.8498
C17: Day 11 | F17: =-246.04-11.35 -> -257.39 | G17: =E17+(F17*$O$3) -> -225.89061 | H17: =G17/$O$9 -> -4.7437028 | I17: =315+G17 -> 89.109388 | K17: 4200
C18: Day 12 | F18: =-90.15 -> -90.15 | G18: =E18+(F18*$O$3) -> -79.117443 | H18: =G18/$O$9 -> -1.6614663 | I18: =315+G18 -> 235.88256
C19: Day 13 | G19: =E19+(F19*$O$3) -> 0 | H19: =G19/$O$9 -> 0 | I19: =315+G19 -> 315 | K19: 3292 | L19: Euros
C20: Day 14 | G20: =E20+(F20*$O$3) -> 0 | H20: =G20/$O$9 -> 0 | I20: =315+G20 -> 315
C21: Day 15 | G21: =E21+(F21*$O$3) -> 0 | H21: =G21/$O$9 -> 0 | I21: =315+G21 -> 315
C22: Day 16 | G22: =E22+(F22*$O$3) -> 0 | H22: =G22/$O$9 -> 0 | I22: =315+G22 -> 315
C23: Day 17 | E23: =76.77 -> 76.77 | F23: =-20.91+8.25-126 -> -138.66 | G23: =E23+(F23*$O$3) -> -44.920789 | H23: =G23/$O$9 -> -0.94333657 | I23: =315+G23 -> 270.07921
C24: Day 18 | F24: =-617.57-7.21 -> -624.78 | G24: =E24+(F24*$O$3) -> -548.31942 | H24: =G24/$O$9 -> -11.514708 | I24: =315+G24 -> -233.31942
C25: Day 19 | G25: =E25+(F25*$O$3) -> 0 | H25: =G25/$O$9 -> 0 | I25: =315+G25 -> 315
C26: Day 20 | F26: =155.7+16.33 -> 172.03 | G26: =E26+(F26*$O$3) -> 150.97697 | H26: =G26/$O$9 -> 3.1705163 | I26: =315+G26 -> 465.97697
C27: Day 21 | F27: =-163.12 -> -163.12 | G27: =E27+(F27*$O$3) -> -143.15737 | H27: =G27/$O$9 -> -3.0063049 | I27: =315+G27 -> 171.84263
C28: Day 22 | G28: =E28+(F28*$O$3) -> 0 | H28: =G28/$O$9 -> 0 | I28: =315+G28 -> 315
C29: Day 23 | G29: =E29+(F29*$O$3) -> 0 | H29: =G29/$O$9 -> 0 | I29: =315+G29 -> 315
C30: Day 24 | G30: =E30+(F30*$O$3) -> 0 | H30: =G30/$O$9 -> 0 | I30: =315+G30 -> 315
C31: Day 25 | F31: =27.13+179.31 -> 206.44 | G31: =E31+(F31*$O$3) -> 181.17587 | H31: =G31/$O$9 -> 3.8046933 | I31: =315+G31 -> 496.17587
C32: Day 26 | G32: =E32+(F32*$O$3) -> 0 | H32: =G32/$O$9 -> 0 | I32: =315+G32 -> 315
C33: Day 27 | F33: =-98.78-0.05 -> -98.83 | G33: =E33+(F33*$O$3) -> -86.735185 | H33: =G33/$O$9 -> -1.8214389 | I33: =315+G33 -> 228.26482
C34: Day 28 | G34: =E34+(F34*$O$3) -> 0 | H34: =G34/$O$9 -> 0 | I34: =315+G34 -> 315
C35: Day 29 | G35: =E35+(F35*$O$3) -> 0 | H35: =G35/$O$9 -> 0 | I35: =315+G35 -> 315
C36: Day 30 | G36: =E36+(F36*$O$3) -> 0 | H36: =G36/$O$9 -> 0 | I36: =315+G36 -> 315
C37: Day 31 | F37: =-47.36 -> -47.36 | G37: =E37+(F37*$O$3) -> -41.564083 | H37: =G37/$O$9 -> -0.87284575 | I37: =315+G37 -> 273.43592

Sheet SET
K2: Valor Conta | L2: EUR | M2: USD | N2: USD em EU
K3: Total | L3: =sum(E7:E37) -> 0 | M3: =sum(F7:F36) -> -675.07 | N3: =M3*Sumario!N4 -> -592.45493 | O3: =Sumario!N4 -> 0.87762
B4: SET
B5: Posicao | C5: Data | D5: Preço Abertura | E5: Lucro EU | F5: Lucro USD | G5: Total EUR
H6: Goal
C7: Day 1 | F7: =-52.82-45.27-44.16-49.7 -> -191.95 | G7: =E7+(F7*$O$3) -> -168.45916 | H7: =G7/$O$9 -> -1.4150569 | I7: =315+G7 -> 146.54084 | K7: =-321-501 -> -822
C8: Day 2 | F8: =-49.97 -> -49.97 | G8: =E8+(F8*$O$3) -> -43.854671 | H8: =G8/$O$9 -> -0.36837924 | I8: =315+G8 -> 271.14533 | N8: Goal | O8: 2500 | P8: =O8-Sumario!K15 -> 3075.4339
C9: Day 3 | F9: =-85.9 -> -85.9 | G9: =E9+(F9*$O$3) -> -75.387558 | H9: =G9/$O$9 -> -0.63325549 | I9: =315+G9 -> 239.61244 | L9: 6930 | N9: Goal Day | O9: =O8/21 -> 119.04762 | P9: =P8/O8 -> 1.2301736
C10: Day 4 | F10: =-46.48-94.04 -> -140.52 | G10: =E10+(F10*$O$3) -> -123.32316 | H10: =G10/$O$9 -> -1.0359146 | I10: =315+G10 -> 191.67684 | L10: =L9+Sumario!K15 -> 6354.5661
C11: Day 5 | G11: =E11+(F11*$O$3) -> 0 | H11: =G11/$O$9 -> 0 | I11: =315+G11 -> 315
C12: Day 6 | G12: =E12+(F12*$O$3) -> 0 | H12: =G12/$O$9 -> 0 | I12: =315+G12 -> 315
C13: Day 7 | G13: =E13+(F13*$O$3) -> 0 | H13: =G13/$O$9 -> 0 | I13: =315+G13 -> 315
C14: Day 8 | F14: =-58.29 -> -58.29 | G14: =E14+(F14*$O$3) -> -51.15647 | H14: =G14/$O$9 -> -0.42971435 | I14: =315+G14 -> 263.84353
C15: Day 9 | G15: =E15+(F15*$O$3) -> 0 | H15: =G15/$O$9 -> 0 | I15: =315+G15 -> 315
C16: Day 10 | G16: =E16+(F16*$O$3) -> 0 | H16: =G16/$O$9 -> 0 | I16: =315+G16 -> 315
C17: Day 11 | G17: =E17+(F17*$O$3) -> 0 | H17: =G17/$O$9 -> 0 | I17: =315+G17 -> 315
C18: Day 12 | G18: =E18+(F18*$O$3) -> 0 | H18: =G18/$O$9 -> 0 | I18: =315+G18 -> 315
C19: Day 13 | G19: =E19+(F19*$O$3) -> 0 | H19: =G19/$O$9 -> 0 | I19: =315+G19 -> 315
C20: Day 14 | G20: =E20+(F20*$O$3) -> 0 | H20: =G20/$O$9 -> 0 | I20: =315+G20 -> 315
C21: Day 15 | G21: =E21+(F21*$O$3) -> 0 | H21: =G21/$O$9 -> 0 | I21: =315+G21 -> 315
C22: Day 16 | G22: =E22+(F22*$O$3) -> 0 | H22: =G22/$O$9 -> 0 | I22: =315+G22 -> 315
C23: Day 17 | F23: =-44.91 -> -44.91 | G23: =E23+(F23*$O$3) -> -39.413914 | H23: =G23/$O$9 -> -0.33107688 | I23: =315+G23 -> 275.58609
C24: Day 18 | F24: =-0.75+68.64 -> 67.89 | G24: =E24+(F24*$O$3) -> 59.581622 | H24: =G24/$O$9 -> 0.50048562 | I24: =315+G24 -> 374.58162
C25: Day 19 | G25: =E25+(F25*$O$3) -> 0 | H25: =G25/$O$9 -> 0 | I25: =315+G25 -> 315
C26: Day 20 | G26: =E26+(F26*$O$3) -> 0 | H26: =G26/$O$9 -> 0 | I26: =315+G26 -> 315
C27: Day 21 | F27: =-48.29-48.97 -> -97.26 | G27: =E27+(F27*$O$3) -> -85.357321 | H27: =G27/$O$9 -> -0.7170015 | I27: =315+G27 -> 229.64268
C28: Day 22 | F28: =0.96+1.12+1.14 -> 3.22 | G28: =E28+(F28*$O$3) -> 2.8259364 | H28: =G28/$O$9 -> 0.023737866 | I28: =315+G28 -> 317.82594
C29: Day 23 | F29: =-27.59-49.79 -> -77.38 | G29: =E29+(F29*$O$3) -> -67.910236 | H29: =G29/$O$9 -> -0.57044598 | I29: =315+G29 -> 247.08976
C30: Day 24 | G30: =E30+(F30*$O$3) -> 0 | H30: =G30/$O$9 -> 0 | I30: =315+G30 -> 315
C31: Day 25 | G31: =E31+(F31*$O$3) -> 0 | H31: =G31/$O$9 -> 0 | I31: =315+G31 -> 315
C32: Day 26 | G32: =E32+(F32*$O$3) -> 0 | H32: =G32/$O$9 -> 0 | I32: =315+G32 -> 315
C33: Day 27 | G33: =E33+(F33*$O$3) -> 0 | H33: =G33/$O$9 -> 0 | I33: =315+G33 -> 315
C34: Day 28 | G34: =E34+(F34*$O$3) -> 0 | H34: =G34/$O$9 -> 0 | I34: =315+G34 -> 315
C35: Day 29 | G35: =E35+(F35*$O$3) -> 0 | H35: =G35/$O$9 -> 0 | I35: =315+G35 -> 315
C36: Day 30 | G36: =E36+(F36*$O$3) -> 0 | H36: =G36/$O$9 -> 0 | I36: =315+G36 -> 315
C37: Day 31 | G37: =E37+(F37*$O$3) -> 0 | H37: =G37/$O$9 -> 0 | I37: =315+G37 -> 315

Sheet OUT
K2: Valor Conta | L2: EUR | M2: USD | N2: USD em EU
K3: Total | L3: =sum(E7:E37) -> 0 | M3: =sum(F7:F37) -> 0 | N3: =M3*Sumario!N4 -> 0 | O3: =Sumario!N4 -> 0.87762
B4: OUT
B5: Posicao | C5: Data | D5: Preço Abertura | E5: Lucro EU | F5: Lucro USD | G5: Total EUR
H6: Goal
C7: Day 1 | G7: =E7+(F7*$O$3) -> 0 | H7: =G7/$O$9 -> 0 | I7: =315+G7 -> 315
C8: Day 2 | G8: =E8+(F8*$O$3) -> 0 | H8: =G8/$O$9 -> 0 | I8: =315+G8 -> 315 | N8: Goal | O8: 2500 | P8: =O8-Sumario!K16 -> 2500
C9: Day 3 | G9: =E9+(F9*$O$3) -> 0 | H9: =G9/$O$9 -> 0 | I9: =315+G9 -> 315 | L9: 7245 | N9: Goal Day | O9: =O8/21 -> 119.04762 | P9: =P8/O8 -> 1
C10: Day 4 | G10: =E10+(F10*$O$3) -> 0 | H10: =G10/$O$9 -> 0 | I10: =315+G10 -> 315 | L10: =L9+Sumario!K16 -> 7245
C11: Day 5 | G11: =E11+(F11*$O$3) -> 0 | H11: =G11/$O$9 -> 0 | I11: =315+G11 -> 315
C12: Day 6 | G12: =E12+(F12*$O$3) -> 0 | H12: =G12/$O$9 -> 0 | I12: =315+G12 -> 315
C13: Day 7 | G13: =E13+(F13*$O$3) -> 0 | H13: =G13/$O$9 -> 0 | I13: =315+G13 -> 315
C14: Day 8 | G14: =E14+(F14*$O$3) -> 0 | H14: =G14/$O$9 -> 0 | I14: =315+G14 -> 315
C15: Day 9 | G15: =E15+(F15*$O$3) -> 0 | H15: =G15/$O$9 -> 0 | I15: =315+G15 -> 315
C16: Day 10 | G16: =E16+(F16*$O$3) -> 0 | H16: =G16/$O$9 -> 0 | I16: =315+G16 -> 315
C17: Day 11 | G17: =E17+(F17*$O$3) -> 0 | H17: =G17/$O$9 -> 0 | I17: =315+G17 -> 315
C18: Day 12 | G18: =E18+(F18*$O$3) -> 0 | H18: =G18/$O$9 -> 0 | I18: =315+G18 -> 315
C19: Day 13 | G19: =E19+(F19*$O$3) -> 0 | H19: =G19/$O$9 -> 0 | I19: =315+G19 -> 315
C20: Day 14 | G20: =E20+(F20*$O$3) -> 0 | H20: =G20/$O$9 -> 0 | I20: =315+G20 -> 315
C21: Day 15 | G21: =E21+(F21*$O$3) -> 0 | H21: =G21/$O$9 -> 0 | I21: =315+G21 -> 315
C22: Day 16 | G22: =E22+(F22*$O$3) -> 0 | H22: =G22/$O$9 -> 0 | I22: =315+G22 -> 315
... C37: Day 31 | G37: =E37+(F37*$O$3) -> 0 | H37: =G37/$O$9 -> 0 | I37: =315+G37 -> 315

Sheet NOV
K2: Valor Conta | L2: EUR | M2: USD | N2: USD em EU
K3: Total | L3: =sum(E7:E37) -> 0 | M3: =sum(F7:F37) -> 0 | N3: =M3*Sumario!N4 -> 0 | O3: =Sumario!N4 -> 0.87762
B4: NOV
B5: Posicao | C5: Data | D5: Preço Abertura | E5: Lucro EU | F5: Lucro USD | G5: Total EUR
H6: Goal
C7: Day 1 | G7: =E7+(F7*$O$3) -> 0 | H7: =G7/$O$9 -> 0 | I7: =315+G7 -> 315
C8: Day 2 | G8: =E8+(F8*$O$3) -> 0 | H8: =G8/$O$9 -> 0 | I8: =315+G8 -> 315 | N8: Goal | O8: 2500 | P8: =O8-Sumario!K17 -> 2500
C9: Day 3 | G9: =E9+(F9*$O$3) -> 0 | H9: =G9/$O$9 -> 0 | I9: =315+G9 -> 315 | L9: 7245 | N9: Goal Day | O9: =O8/21 -> 119.04762 | P9: =P8/O8 -> 1
C10: Day 4 | G10: =E10+(F10*$O$3) -> 0 | H10: =G10/$O$9 -> 0 | I10: =315+G10 -> 315 | L10: =L9+Sumario!K16 -> 7245
C11: Day 5 | G11: =E11+(F11*$O$3) -> 0 | H11: =G11/$O$9 -> 0 | I11: =315+G11 -> 315
C12: Day 6 | G12: =E12+(F12*$O$3) -> 0 | H12: =G12/$O$9 -> 0 | I12: =315+G12 -> 315
C13: Day 7 | G13: =E13+(F13*$O$3) -> 0 | H13: =G13/$O$9 -> 0 | I13: =315+G13 -> 315
C14: Day 8 | G14: =E14+(F14*$O$3) -> 0 | H14: =G14/$O$9 -> 0 | I14: =315+G14 -> 315
C15: Day 9 | G15: =E15+(F15*$O$3) -> 0 | H15: =G15/$O$9 -> 0 | I15: =315+G15 -> 315
C16: Day 10 | G16: =E16+(F16*$O$3) -> 0 | H16: =G16/$O$9 -> 0 | I16: =315+G16 -> 315
C17: Day 11 | G17: =E17+(F17*$O$3) -> 0 | H17: =G17/$O$9 -> 0 | I17: =315+G17 -> 315
C18: Day 12 | G18: =E18+(F18*$O$3) -> 0 | H18: =G18/$O$9 -> 0 | I18: =315+G18 -> 315
C19: Day 13 | G19: =E19+(F19*$O$3) -> 0 | H19: =G19/$O$9 -> 0 | I19: =315+G19 -> 315
C20: Day 14 | G20: =E20+(F20*$O$3) -> 0 | H20: =G20/$O$9 -> 0 | I20: =315+G20 -> 315
C21: Day 15 | G21: =E21+(F21*$O$3) -> 0 | H21: =G21/$O$9 -> 0 | I21: =315+G21 -> 315
C22: Day 16 | G22: =E22+(F22*$O$3) -> 0 | H22: =G22/$O$9 -> 0 | I22: =315+G22 -> 315
... C37: Day 31 | G37: =E37+(F37*$O$3) -> 0 | H37: =G37/$O$9 -> 0 | I37: =315+G37 -> 315

Sheet DEZ
K2: Valor Conta | L2: EUR | M2: USD | N2: USD em EU
K3: Total | L3: =sum(E7:E37) -> 0 | M3: =sum(F7:F37) -> 0 | N3: =M3*Sumario!N4 -> 0 | O3: =Sumario!N4 -> 0.87762
B4: DEZ
B5: Posicao | C5: Data | D5: Preço Abertura | E5: Lucro EU | F5: Lucro USD | G5: Total EUR
H6: Goal
C7: Day 1 | G7: =E7+(F7*$O$3) -> 0 | H7: =G7/$O$9 -> 0 | I7: =315+G7 -> 315
C8: Day 2 | G8: =E8+(F8*$O$3) -> 0 | H8: =G8/$O$9 -> 0 | I8: =315+G8 -> 315 | N8: Goal | O8: 2500 | P8: =O8-Sumario!K18 -> 2500
C9: Day 3 | G9: =E9+(F9*$O$3) -> 0 | H9: =G9/$O$9 -> 0 | I9: =315+G9 -> 315 | L9: 7245 | N9: Goal Day | O9: =O8/21 -> 119.04762 | P9: =P8/O8 -> 1
C10: Day 4 | G10: =E10+(F10*$O$3) -> 0 | H10: =G10/$O$9 -> 0 | I10: =315+G10 -> 315 | L10: =L9+Sumario!K16 -> 7245
C11: Day 5 | G11: =E11+(F11*$O$3) -> 0 | H11: =G11/$O$9 -> 0 | I11: =315+G11 -> 315
C12: Day 6 | G12: =E12+(F12*$O$3) -> 0 | H12: =G12/$O$9 -> 0 | I12: =315+G12 -> 315
C13: Day 7 | G13: =E13+(F13*$O$3) -> 0 | H13: =G13/$O$9 -> 0 | I13: =315+G13 -> 315
C14: Day 8 | G14: =E14+(F14*$O$3) -> 0 | H14: =G14/$O$9 -> 0 | I14: =315+G14 -> 315
C15: Day 9 | G15: =E15+(F15*$O$3) -> 0 | H15: =G15/$O$9 -> 0 | I15: =315+G15 -> 315
C16: Day 10 | G16: =E16+(F16*$O$3) -> 0 | H16: =G16/$O$9 -> 0 | I16: =315+G16 -> 315
C17: Day 11 | G17: =E17+(F17*$O$3) -> 0 | H17: =G17/$O$9 -> 0 | I17: =315+G17 -> 315
C18: Day 12 | G18: =E18+(F18*$O$3) -> 0 | H18: =G18/$O$9 -> 0 | I18: =315+G18 -> 315
C19: Day 13 | G19: =E19+(F19*$O$3) -> 0 | H19: =G19/$O$9 -> 0 | I19: =315+G19 -> 315
C20: Day 14 | G20: =E20+(F20*$O$3) -> 0 | H20: =G20/$O$9 -> 0 | I20: =315+G20 -> 315
C21: Day 15 | G21: =E21+(F21*$O$3) -> 0 | H21: =G21/$O$9 -> 0 | I21: =315+G21 -> 315
C22: Day 16 | G22: =E22+(F22*$O$3) -> 0 | H22: =G22/$O$9 -> 0 | I22: =315+G22 -> 315
... C37: Day 31 | G37: =E37+(F37*$O$3) -> 0 | H37: =G37/$O$9 -> 0 | I37: =315+G37 -> 315

Sheet Configs
A1: Configs
A2: processarLoteItems | B2: FALSE | C2: A função processarLoteItems é um motor de execução em lotes resiliente, desenhado para processar chamadas de API (como o envio de ordens de trading) diretamente a partir do Google Sheets, garantindo que os limites de tempo do Google e os limites de taxa da API não são excedidos.
A3: processarTudo | B3: FALSE
A4: processarLoteItems_Short | B4: FALSE
A5: enviarRelatorioIA | B5: FALSE
A6: riscoMaximoDolares | B6: 25
A7: racioTakeProfit | C7: Colocar o valor temporáriamente. Por defeito assume os valores standard 1.5 e 2.0.
A8: multiplicadorTrailing | B8: 2 | C8: 1.5 (Stop Apertado / Conservador): É o valor por defeito. É excelente para mercados muito voláteis, ou quando a ação já subiu muito e tu queres trancar o máximo de lucro possível ao primeiro sinal de fraqueza. A desvantagem? Podes ser "expulso" da posição num dia de queda normal, antes da ação voltar a subir. 2.0 (O Padrão de Ouro / Moderado): É o valor clássico do famoso indicador Chandelier Exit. Dá espaço suficiente para a ação sofrer o seu "ruído" normal do dia-a-dia (quedas normais numa tendência de alta) sem te fechar a posição prematuramente. É o ideal para deixar os lucros correrem. 2.5 a 3.0 (Stop Largo / Seguidor de Tendência): Usado apenas se quiseres segurar a ação durante meses (como a VISA, que é uma ação muito estável a longo prazo). Dá imenso espaço para a ação corrigir, mas significa que devolves uma parte maior do lucro ao mercado se a tendência reverter. | D8: 0
A9: analiseTecnica | B9: FALSE
A10: listaAtivosPermitidos | B10: NOW,AMZN, WMT, PG, PEP,TSLA,BRK.B, VISA, MA,LLY, UNH,AAPL, MSFT, GOOGL, NVDA, AVGO, ASML,ADBE, CRM, SAP, ORCL, AMD, INTC, DELL, PANW, PLTR, NET, CSCO, MRVL, MCHP, QLYS, IBM, TYL, VRSK,NKE, BABA, PDD, SHOP, EBAY, EL, BOSS, UBER, DASH, OR, HEIA, NFLX,BMW, MBG, VOW3, P911, BYDDY, SIE, LMT, RHM, GRMN, SWK, TKA,PFE, ABT, NOVN, MRNA, HUM,UPST,ANF,ASTS,QLYS,NET,NFLX,ADP,BBAI,META | C10: Short List para processamento | D10: =IFERROR(__xludf.DUMMYFUNCTION("IF(B10="""", 0, COUNTA(SPLIT(B10, "","")))"),71.0) -> 71
A11: listaAllStocks | B11: ANF, ACN, ADS, ADBE, ADYEN, AHL, A, BABA, ALV, GOOGL, AMZ, AMZN, AMD, AS, AMPL, APCA, AAPL, APP, ANET, ASML, ASTS, TEAM, BAYN, BRK.B, BBAI, BMW, BABA, BOSS, AVGO, BYDDY, AI, CAP, CELH, CNA, CSCO, CLSK, NET, CNXC, COND, TG, DBX, BROS, EBAY, LLY, ENVX, EL, GALP, GRMN, HEIA, HEN3, HSBA, HSBC, IDR, IFX, INL, INTC, IONQ, LMT, OR, MRVL, M4I, MA, MBG, META, MSFT, MRNA, MNDY, NFC, NFLX, NKE, NKE, NOVN, NOVN, VONV, D, NVDA, ORC, ORCL, PTX, PLTR, PANW, 2PP, PDD, PEP, PHIA, P911, PRG, PG, PG, QLYS, QUBT, QSR, L, RHM, RGTI, HOOD, RKLB, RGLD, FOO, CRM, SAP, LAE, SNOW, SHAK, SIE, SWK, SG, LE, SOON, SOUN, STR, SMCI, TALK, TEM, TSLA, TL0, TKA, TTD, UT8, UNH, U, UPST, VISA, VOW3, WMT, WMT, DELL, SHELL, SHOP, PFE, RDDT, RBLX, FITB, RCAT, MCHP, ARES, BMI, UBER, FIG, HUM, TZOO, VRSK, TYL, DDOG, ABT, IBM, DASH | C11: All Stocks | D11: =IFERROR(__xludf.DUMMYFUNCTION("IF(B11="""", 0, COUNTA(SPLIT(B11, "","")))"),147.0) -> 147
A12: listaLightStocks | B12: NOW,AMZN, WMT, PG, PEP,TSLA,BRK.B, VISA, MA,LLY, UNH,AAPL, MSFT, GOOGL, NVDA, AVGO, ASML,ADBE, CRM, SAP, ORCL, AMD, INTC, DELL, PANW, PLTR, NET, CSCO, MRVL, MCHP, QLYS, IBM, TYL, VRSK,NKE, BABA, PDD, SHOP, EBAY, EL, BOSS, UBER, DASH, OR, HEIA, NFLX,BMW, MBG, VOW3, P911, BYDDY, SIE, LMT, RHM, GRMN, SWK, TKA,PFE, ABT, NOVN, MRNA, HUM | C12: Light Stocks | D12: =IFERROR(__xludf.DUMMYFUNCTION("IF(B12="""", 0, COUNTA(SPLIT(B12, "","")))"),62.0) -> 62
E16: Estados usados no Diario de Bordo
E17: PENDENTE | F17: A ordem Buy Limit está colocada na corretora. O setup é válido e aguarda que o preço recue até à Drop Zone.
E18: ATIVA | F18: A ordem Limit foi acionada. O capital está no mercado e o Hard Stop de proteção está obrigatoriamente colocado na corretora.
E19: WIN | F19: A ação seguiu a tendência e atingiu o teu alvo quantitativo.
E20: LOSS | F20: O mercado invalidou a tese. O Hard Stop cortou o risco ao nível predefinido (~$50).
E21: FUGIU | F21: O ativo arrancou sem acionar a ordem. A janela de oportunidade fechou e a ordem foi cancelada para proteger a margem e evitar "facas a cair".
E22: INVALIDADO | F22: A ordem limite estava pendente, mas os filtros técnicos que a justificavam (como o RVOL a cair abaixo de 1.0 ou o ADX a perder força) deterioraram-se antes de o preço chegar à Drop Zone.
E23: BREAKEVEN

Sheet Analise Compra
E2: Stock | F2: Description | G2: Market Price | H2: L | I2: H | J2: Result | K2: Momentum | L2: RSI | M2: ADX | N2: ATR | O2: Pivot | P2: Price | Q2: Time | R2: true | S2: ERRO: Cannot read properties of undefined (reading '0') | T2: 0 | U2: Ticker | V2: Ticker Price | W2: distMM20 | X2: Momentum 2 | Y2: RSI 2 | Z2: ADX 2 | AA2: ATR 2 | AB2: VOL | AC2: Column 1 | AD2: Drop Zone | AE2: Column 2 | AF2: Column 3 | AG2: Column 4 | AH2: Column 5
E3: AAPL | F3: Apple US | G3: =IFERROR(__xludf.DUMMYFUNCTION("GOOGLEFINANCE(E3, ""price"")"),336.89) -> 336.89 | H3: =IFERROR(__xludf.DUMMYFUNCTION("GOOGLEFINANCE(E3, ""low"")"),335.91) -> 335.91 | I3: =IFERROR(__xludf.DUMMYFUNCTION("GOOGLEFINANCE(E3, ""high"")"),341.8) -> 341.8 | K3: 11.27 | L3: 59.69 | M3: 19.99 | N3: 5.47 | O3: P Down | P3: 205.2 | Q3: 45761.644 | R3: TRUE | S3: AAPL,Preço: 339.75,Dist MM20: 4.35%,Momentum: 14.62,RSI: 66.88,ADX: 18.67,ATR: 6.97,RVOL: 0.94,Estado: Aguardar Recuo,Entrada: 336.96,Stop: 329.99,Take-Profit: 345.32,Break-Even: 341.14,Qtd: 3.59,Trailing: 329.99,Data: 23/09/2026 02:04:29 | T3: 0 | U3: AAPL | V3: Preço: 333.43 | W3: Dist MM20: 2.80% | X3: Momentum: 18.11 | Y3: RSI: 61.66 | Z3: ADX: 29.46 | AA3: ATR: 7.30 | AB3: RVOL: 1.11 | AC3: Data: 31/07/2026 02:06:15 | AD3: 46030.371 | AE3: AAPL,Preço: 333.43,Dist MM20: 2.80%,Momentum: 18.11,RSI: 61.66,ADX: 29.46,ATR: 7.30,RVOL: 1.11,Estado: Observar,Entrada: N/A,Stop: N/A,Take-Profit: N/A,Break-Even: N/A,Qtd: N/A,Data: 31/07/2026 02:06:15
B4: Time Now | C4: =now() -> 46288.715 | E4: ABNB | F4: Airbnb | G4: =IFERROR(__xludf.DUMMYFUNCTION("GOOGLEFINANCE(E4, ""price"")"),152.37) -> 152.37 | R4: TRUE | S4: ABNB,Preço: 161.81,Dist MM20: -8.01%,Momentum: -20.73,RSI: 35.83,ADX: 23.28,ATR: 4.55,RVOL: 1.11,Estado: Observar,Entrada: N/A,Stop: N/A,Take-Profit: N/A,Break-Even: N/A,Qtd: N/A,Trailing: 152.71,Data: 23/09/2026 06:43:09 | T4: 0 | U4: ABNB | V4: Preço: 152.08 | W4: Dist MM20: 3.75% | X4: Momentum: 3.46 | Y4: RSI: 60.76 | Z4: ADX: 16.86 | AA4: ATR: 3.81 | AB4: RVOL: 0.90 | AC4: Data: 31/07/2026 04:52:48 | AD4: 46030.371 | AE4: ABNB,Preço: 152.08,Dist MM20: 3.75%,Momentum: 3.46,RSI: 60.76,ADX: 16.86,ATR: 3.81,RVOL: 0.90,Estado: Observar,Entrada: N/A,Stop: N/A,Take-Profit: N/A,Break-Even: N/A,Qtd: N/A,Data: 31/07/2026 04:52:48
E5: ABT | F5: Abbot Laboratories | G5: =IFERROR(__xludf.DUMMYFUNCTION("GOOGLEFINANCE(E5, ""price"")"),104.05) -> 104.05 | H5: =IFERROR(__xludf.DUMMYFUNCTION("GOOGLEFINANCE(E5, ""low"")"),102.85) -> 102.85 | I5: =IFERROR(__xludf.DUMMYFUNCTION("GOOGLEFINANCE(E5, ""high"")"),104.29) -> 104.29 | K5: 7.93 | L5: 0 | M5: 21.44 | N5: 3.13 | R5: TRUE | S5: ABT,Preço: 103.69,Dist MM20: -2.92%,Momentum: -5.24,RSI: 42.27,ADX: 25.38,ATR: 2.31,RVOL: 0.96,Estado: Observar,Entrada: N/A,Stop: N/A,Take-Profit: N/A,Break-Even: N/A,Qtd: N/A,Trailing: 99.07,Data: 23/09/2026 02:04:47 | T5: 0 | U5: ABT | V5: Preço: 105.61 | W5: Dist MM20: 7.15% | X5: Momentum: 11.68 | Y5: RSI: 66.64 | Z5: ADX: 31.05 | AA5: ATR: 2.71 | AB5: RVOL: 0.50 | AC5: Data: 31/07/2026 02:37:35 | AD5: 46030.371 | AE5: ABT,Preço: 105.61,Dist MM20: 7.15%,Momentum: 11.68,RSI: 66.64,ADX: 31.05,ATR: 2.71,RVOL: 0.50,Estado: Observar,Entrada: N/A,Stop: N/A,Take-Profit: N/A,Break-Even: N/A,Qtd: N/A,Data: 31/07/2026 02:37:35
E6: ACN | F6: Accenture | G6: =IFERROR(__xludf.DUMMYFUNCTION("GOOGLEFINANCE(E6, ""price"")"),185.3) -> 185.3 | H6: =IFERROR(__xludf.DUMMYFUNCTION("GOOGLEFINANCE(E6, ""low"")"),182.56) -> 182.56 | I6: =IFERROR(__xludf.DUMMYFUNCTION("GOOGLEFINANCE(E6, ""high"")"),188.28) -> 188.28 | K6: -4.31 | L6: 47.14 | M6: 13.93 | N6: 5.42 | O6: S1 Up | P6: 311.07 | Q6: 45828.334 | R6: TRUE | S6: ACN,Preço: 183.72,Dist MM20: -1.40%,Momentum: -4.37,RSI: 51.15,ADX: 18.44,ATR: 6.24,RVOL: 0.80,Estado: Observar,Entrada: N/A,Stop: N/A,Take-Profit: N/A,Break-Even: N/A,Qtd: N/A,Trailing: 171.24,Data: 23/09/2026 06:44:26 | T6: 0 | U6: ACN | V6: Preço: 163.29 | W6: Dist MM20: 12.89% | X6: Momentum: 28.06 | Y6: RSI: 60.57 | Z6: ADX: 21.73 | AA6: ATR: 6.90 | AB6: RVOL: 1.02 | AC6: Data: 31/07/2026 03:50:33 | AD6: 46030.371 | AE6: ACN,Preço: 163.29,Dist MM20: 12.89%,Momentum: 28.06,RSI: 60.57,ADX: 21.73,ATR: 6.90,RVOL: 1.02,Estado: Observar,Entrada: N/A,Stop: N/A,Take-Profit: N/A,Break-Even: N/A,Qtd: N/A,Data: 31/07/2026 03:50:33
E7: ADBE | F7: Adobe Inc US | G7: =IFERROR(__xludf.DUMMYFUNCTION("GOOGLEFINANCE(E7, ""price"")"),240.71) -> 240.71 | H7: =IFERROR(__xludf.DUMMYFUNCTION("GOOGLEFINANCE(E7, ""low"")"),237.51) -> 237.51 | I7: =IFERROR(__xludf.DUMMYFUNCTION("GOOGLEFINANCE(E7, ""high"")"),241.69) -> 241.69 | R7: TRUE | S7: ADBE,Preço: 238.25,Dist MM20: -10.35%,Momentum: -47.83,RSI: 37.39,ADX: 21.84,ATR: 8.84,RVOL: 1.28,Estado: Observar,Entrada: N/A,Stop: N/A,Take-Profit: N/A,Break-Even: N/A,Qtd: N/A,Trailing: 220.57,Data: 23/09/2026 02:05:04 | T7: 0 | U7: ADBE | V7: Preço: 247.90 | W7: Dist MM20: 8.00% | X7: Momentum: 24.26 | Y7: RSI: 58.84 | Z7: ADX: 17.19 | AA7: ATR: 10.79 | AB7: RVOL: 1.18 | AC7: Data: 31/07/2026 02:04:27 | AD7: 46030.371 | AE7: ADBE,Preço: 247.90,Dist MM20: 8.00%,Momentum: 24.26,RSI: 58.84,ADX: 17.19,ATR: 10.79,RVOL: 1.18,Estado: Observar,Entrada: N/A,Stop: N/A,Take-Profit: N/A,Break-Even: N/A,Qtd: N/A,Data: 31/07/2026 02:04:27
E8: ADP | F8: Automatic Data Processing | G8: =IFERROR(__xludf.DUMMYFUNCTION("GOOGLEFINANCE(E8, ""price"")"),267.39) -> 267.39 | R8: TRUE | S8: ADP,Preço: 269.64,Dist MM20: -2.42%,Momentum: -13.85,RSI: 46.09,ADX: 19.79,ATR: 4.78,RVOL: 0.86,Estado: Observar,Entrada: N/A,Stop: N/A,Take-Profit: N/A,Break-Even: N/A,Qtd: N/A,Trailing: 260.08,Data: 23/09/2026 02:05:22 | T8: 0 | U8: ADP | V8: Preço: 270.62 | W8: Dist MM20: 6.50% | X8: Momentum: 23.15 | Y8: RSI: 67.16 | Z8: ADX: 36.53 | AA8: ATR: 8.27 | AB8: RVOL: 1.03 | AC8: Trailing: 259.05 | AD8: 46150.444 | AE8: ADP,Preço: 270.62,Dist MM20: 6.50%,Momentum: 23.15,RSI: 67.16,ADX: 36.53,ATR: 8.27,RVOL: 1.03,Estado: Forca Consolidada,Entrada: 268.97,Stop: 259.05,Take-Profit: 283.86,Break-Even: 276.42,Qtd: 5.04,Trailing: 259.05,Data: 05/08/2026 10:33:05
E9: ADSK | F9: AutoDesk | G9: =IFERROR(__xludf.DUMMYFUNCTION("GOOGLEFINANCE(E9, ""price"")"),219.03) -> 219.03 | H9: =IFERROR(__xludf.DUMMYFUNCTION("GOOGLEFINANCE(F9, ""price"")"),"#N/A") -> #N/A | I9: =IFERROR(__xludf.DUMMYFUNCTION("GOOGLEFINANCE(G9, ""price"")"),"#N/A") -> #N/A | R9: TRUE | S9: ADSK,Preço: 219.62,Dist MM20: -5.20%,Momentum: -28.07,RSI: 42.82,ADX: 20.86,ATR: 8.05,RVOL: 0.69,Estado: Observar,Entrada: N/A,Stop: N/A,Take-Profit: N/A,Break-Even: N/A,Qtd: N/A,Trailing: 203.52,Data: 23/09/2026 06:44:26 | T9: 0 | U9: ADSK | V9: Preço: 234.97 | W9: Dist MM20: 9.19% | X9: Momentum: 26.52 | Y9: RSI: 61.81 | Z9: ADX: 17.19 | AA9: ATR: 8.60 | AB9: RVOL: 1.06 | AC9: Data: 31/07/2026 04:53:43 | AD9: 46030.371 | AE9: ADSK,Preço: 234.97,Dist MM20: 9.19%,Momentum: 26.52,RSI: 61.81,ADX: 17.19,ATR: 8.60,RVOL: 1.06,Estado: Observar,Entrada: N/A,Stop: N/A,Take-Profit: N/A,Break-Even: N/A,Qtd: N/A,Data: 31/07/2026 04:53:43
E10: ADYEN | F10: Adyen | G10: =IFERROR(__xludf.DUMMYFUNCTION("GOOGLEFINANCE(E10, ""price"")"),860.1) -> 860.1 | H10: =IFERROR(__xludf.DUMMYFUNCTION("GOOGLEFINANCE(E10, ""low"")"),856.0) -> 856 | I10: =IFERROR(__xludf.DUMMYFUNCTION("GOOGLEFINANCE(E10, ""high"")"),899.6) -> 899.6 | K10: 246.4 | L10: 80.15 | M10: 24.54 | N10: 51.6 | O10: R3 Down | P10: 1835.8 | Q10: 45707.814 | R10: TRUE | S10: ADYEN,Preço: 903.00,Dist MM20: -7.75%,Momentum: -135.60,RSI: 38.93,ADX: 29.54,ATR: 25.59,RVOL: 1.06,Estado: Observar,Entrada: N/A,Stop: N/A,Take-Profit: N/A,Break-Even: N/A,Qtd: N/A,Trailing: 851.82,Data: 23/09/2026 06:44:29 | T10: 0 | U10: ADYEN | V10: Preço: 885.20 | W10: Dist MM20: 4.85% | X10: Momentum: 38.60 | Y10: RSI: 57.69 | Z10: ADX: 14.69 | AA10: ATR: 31.76 | AB10: RVOL: 0.85 | AC10: Data: 31/07/2026 03:51:07 | AD10: 46030.371 | AE10: ADYEN,Preço: 885.20,Dist MM20: 4.85%,Momentum: 38.60,RSI: 57.69,ADX: 14.69,ATR: 31.76,RVOL: 0.85,Estado: Aguardar Recuo,Entrada: 872.50,Stop: 840.74,Take-Profit: 936.02,Break-Even: 904.26,Qtd: 1.57,Data: 31/07/2026 03:51:07
E11: AEP | F11: American Electric Power | G11: =IFERROR(__xludf.DUMMYFUNCTION("GOOGLEFINANCE(E11, ""price"")"),118.06) -> 118.06 | R11: TRUE | S11: AEP,Preço: 120.27,Dist MM20: -1.89%,Momentum: -2.69,RSI: 35.97,ADX: 21.24,ATR: 1.89,RVOL: 1.31,Estado: Observar,Entrada: N/A,Stop: N/A,Take-Profit: N/A,Break-Even: N/A,Qtd: N/A,Trailing: 116.49,Data: 23/09/2026 06:44:27 | T11: 0 | U11: AEP | V11: Preço: 127.78 | W11: Dist MM20: -4.44% | X11: Momentum: -7.65 | Y11: RSI: 37.84 | Z11: ADX: 12.60 | AA11: ATR: 2.66 | AB11: RVOL: 1.35 | AC11: Data: 31/07/2026 04:53:26 | AD11: 46030.371 | AE11: AEP,Preço: 127.78,Dist MM20: -4.44%,Momentum: -7.65,RSI: 37.84,ADX: 12.60,ATR: 2.66,RVOL: 1.35,Estado: Observar,Entrada: N/A,Stop: N/A,Take-Profit: N/A,Break-Even: N/A,Qtd: N/A,Data: 31/07/2026 04:53:26
E12: AGNC | F12: AGNC Investments | G12: =IFERROR(__xludf.DUMMYFUNCTION("GOOGLEFINANCE(E12, ""price"")"),9.95) -> 9.95 | R12: TRUE | S12: AGNC,Preço: 10.09,Dist MM20: -3.04%,Momentum: -0.51,RSI: 37.10,ADX: 26.49,ATR: 0.20,RVOL: 0.84,Estado: Observar,Entrada: N/A,Stop: N/A,Take-Profit: N/A,Break-Even: N/A,Qtd: N/A,Trailing: 9.69,Data: 23/09/2026 06:44:27 | T12: 0 | U12: AGNC | V12: Preço: 10.64 | W12: Dist MM20: -2.53% | X12: Momentum: -0.68 | Y12: RSI: 45.08 | Z12: ADX: 16.75 | AA12: ATR: 0.23 | AB12: RVOL: 1.27 | AC12: Trailing: 10.18 | AD12: 46150.444 | AE12: AGNC,Preço: 10.64,Dist MM20: -2.53%,Momentum: -0.68,RSI: 45.08,ADX: 16.75,ATR: 0.23,RVOL: 1.27,Estado: Observar,Entrada: N/A,Stop: N/A,Take-Profit: N/A,Break-Even: N/A,Qtd: N/A,Trailing: 10.18,Data: 05/08/2026 10:28:13
E13: AI | F13: C3.ai | G13: =IFERROR(__xludf.DUMMYFUNCTION("GOOGLEFINANCE(E13, ""price"")"),10.89) -> 10.89 | K13: 2.45 | L13: 58 | M13: 27.5 | N13: 1.61 | O13: S1 Up | P13: 25.85 | Q13: 45812.512 | R13: TRUE | S13: AI,Preço: 10.85,Dist MM20: 2.96%,Momentum: 0.51,RSI: 56.45,ADX: 24.07,ATR: 0.50,RVOL: 0.72,Estado: Observar,Entrada: N/A,Stop: N/A,Take-Profit: N/A,Break-Even: N/A,Qtd: N/A,Trailing: 9.85,Data: 23/09/2026 06:49:38 | T13: 0 | U13: AI | V13: Preço: 9.07 | W13: Dist MM20: 2.72% | X13: Momentum: 0.12 | Y13: RSI: 51.28 | Z13: ADX: 16.64 | AA13: ATR: 0.45 | AB13: RVOL: 0.72 | AC13: Data: 31/07/2026 03:53:52 | AD13: 46030.371 | AE13: AI,Preço: 9.07,Dist MM20: 2.72%,Momentum: 0.12,RSI: 51.28,ADX: 16.64,ATR: 0.45,RVOL: 0.72,Estado: Aguardar Recuo,Entrada: 8.89,Stop: 8.44,Take-Profit: 9.79,Break-Even: 9.34,Qtd: 111.11,Data: 31/07/2026 03:53:52
E14: ALTG | F14: Alta Equipment | G14: =IFERROR(__xludf.DUMMYFUNCTION("GOOGLEFINANCE(E14, ""price"")"),6.19) -> 6.19 | R14: TRUE | S14: ALTG,Preço: 6.28,Dist MM20: 5.04%,Momentum: 0.56,RSI: 52.49,ADX: 18.57,ATR: 0.32,RVOL: 1.19,Estado: Aguardar Recuo,Entrada: 6.15,Stop: 5.83,Take-Profit: 6.53,Break-Even: 6.34,Qtd: 78.12,Trailing: 5.83,Data: 23/09/2026 06:49:55 | T14: 0 | U14: ALTG | V14: Preço: 6.07 | W14: Dist MM20: -4.54% | X14: Momentum: -0.55 | Y14: RSI: 42.11 | Z14: ADX: 9.80 | AA14: ATR: 0.39 | AB14: RVOL: 0.57 | AC14: Data: 31/07/2026 04:50:03 | AD14: 46030.371 | AE14: ALTG,Preço: 6.07,Dist MM20: -4.54%,Momentum: -0.55,RSI: 42.11,ADX: 9.80,ATR: 0.39,RVOL: 0.57,Estado: Aguardar Recuo,Entrada: 5.91,Stop: 5.52,Take-Profit: 6.69,Break-Even: 6.30,Qtd: 128.21,Data: 31/07/2026 04:50:03
B15: Time Now | C15: =now() -> 46288.715 | E15: AMD | F15: AMD US | G15: =IFERROR(__xludf.DUMMYFUNCTION("GOOGLEFINANCE(E15, ""price"")"),612.95) -> 612.95 | H15: =IFERROR(__xludf.DUMMYFUNCTION("GOOGLEFINANCE(E15, ""low"")"),608.08) -> 608.08 | I15: =IFERROR(__xludf.DUMMYFUNCTION("GOOGLEFINANCE(E15, ""high"")"),624.69) -> 624.69 | R15: TRUE | S15: AMD,Preço: 623.77,Dist MM20: 23.22%,Momentum: 164.16,RSI: 73.88,ADX: 19.74,ATR: 19.97,RVOL: 1.33,Estado: Aguardar Recuo,Entrada: 615.78,Stop: 595.81,Take-Profit: 639.74,Break-Even: 627.76,Qtd: 1.25,Trailing: 595.81,Data: 23/09/2026 02:05:39 | T15: 0 | U15: AMD | V15: Preço: 485.39 | W15: Dist MM20: -6.14% | X15: Momentum: -72.50 | Y15: RSI: 46.51 | Z15: ADX: 15.51 | AA15: ATR: 33.75 | AB15: RVOL: 1.26 | AC15: Data: 31/07/2026 02:05:58 | AD15: 46030.371 | AE15: AMD,Preço: 485.39,Dist MM20: -6.14%,Momentum: -72.50,RSI: 46.51,ADX: 15.51,ATR: 33.75,RVOL: 1.26,Estado: Aguardar Recuo,Entrada: 471.89,Stop: 438.14,Take-Profit: 539.39,Break-Even: 505.64,Qtd: 1.48,Data: 31/07/2026 02:05:58
